<?xml version='1.0' encoding='UTF-8'?>
<mujoco model="ur3">
  <compiler angle="radian" meshdir="C:/Users/smart/Downloads/urdf_files/mat/desc/meshes/ur3/collision/"/>

  <asset>
    <mesh name="bases" file="bases.stl"/>
    <mesh name="shoulder" file="shoulder.stl"/>
    <mesh name="upperarm" file="upperarm.stl"/>
    <mesh name="forearm" file="forearm.stl"/>
    <mesh name="wrist1" file="wrist1.stl"/>
    <mesh name="wrist2" file="wrist2.stl"/>
    <mesh name="wrist3" file="wrist3.stl"/>
  </asset>

  <worldbody>
    <body name="base_link">
      <inertial pos="0 0 0" quat="0.5 0.5 -0.5 0.5" mass="2" diaginertia="0.005625 0.00305317 0.00305317"/>
      <geom type="mesh" rgba="0.7 0.7 0.7 1" mesh="bases"/>
      <body name="shoulder_link" pos="0 0 0.1519">
        <inertial pos="0 0 0" mass="2.5" diaginertia="0.009 0.009 0.006"/>
        <joint name="shoulder_pan_joint" pos="0 0 0" axis="0 0 1" range="-6.28319 6.28319" actuatorfrcrange="-330 330" armature="0.01"/>
        <geom type="mesh" rgba="0.7 0.7 0.7 1" mesh="shoulder"/>
        <body name="upper_arm_link" pos="0 0.1198 0" quat="0.707107 0 0.707107 0">
          <inertial pos="0 0 0.121825" mass="3.6" diaginertia="0.022 0.022 0.010"/>
          <joint name="shoulder_lift_joint" pos="0 0 0" axis="0 1 0" range="-6.28319 6.28319" actuatorfrcrange="-330 330" armature="0.01"/>
          <geom type="mesh" rgba="0.7 0.7 0.7 1" mesh="upperarm"/>
          <body name="forearm_link" pos="0 -0.0925 0.24365">
            <inertial pos="0 0 0.106625" mass="1.3" diaginertia="0.007 0.007 0.004"/>
            <joint name="elbow_joint" pos="0 0 0" axis="0 1 0" range="-3.14159 3.14159" actuatorfrcrange="-150 150" armature="0.01"/>
            <geom type="mesh" rgba="0.7 0.7 0.7 1" mesh="forearm"/>
            <body name="wrist_1_link" pos="0 0 0.21325" quat="0.707107 0 0.707107 0">
              <inertial pos="0 0 0" quat="0.5 0.5 -0.5 0.5" mass="0.85" diaginertia="0.0023 0.0021 0.0021"/>
              <joint name="wrist_1_joint" pos="0 0 0" axis="0 1 0" range="-6.28319 6.28319" actuatorfrcrange="-54 54" armature="0.01"/>
              <geom type="mesh" rgba="0.7 0.7 0.7 1" mesh="wrist1"/>
              <body name="wrist_2_link" pos="0 0.08505 0">
                <inertial pos="0 0 0" quat="0.5 0.5 -0.5 0.5" mass="0.85" diaginertia="0.0023 0.0021 0.0021"/>
                <joint name="wrist_2_joint" pos="0 0 0" axis="0 0 1" range="-6.28319 6.28319" actuatorfrcrange="-54 54" armature="0.01"/>
                <geom type="mesh" rgba="0.7 0.7 0.7 1" mesh="wrist2"/>
                <body name="wrist_3_link" pos="0 0 0.08535">
                  <inertial pos="0 0 0" quat="0.5 0.5 -0.5 0.5" mass="0.4" diaginertia="0.001 0.0009 0.0009"/>
                  <joint name="wrist_3_joint" pos="0 0 0" axis="0 1 0" range="-6.28319 6.28319" actuatorfrcrange="-54 54" armature="0.01"/>
                  <geom type="mesh" rgba="0.7 0.7 0.7 1" mesh="wrist3"/>
                  <body name="ee_link" pos="0 0.0819 0" quat="0.707107 0 0 0.707107">
                    <geom size="0.005 0.005 0.005" pos="-0.01 0 0" type="box"/>
                  </body>
                  <body name="tool0" pos="0 0.0819 0" quat="0.707107 -0.707107 0 0"/>
                </body>
              </body>
            </body>
          </body>
        </body>
      </body>
      <body name="base" quat="0 0 0 -1"/>
    </body>
  </worldbody>
<actuator><motor name="motor_shoulder_pan" joint="shoulder_pan_joint" ctrlrange="-330 330"/><motor name="motor_shoulder_lift" joint="shoulder_lift_joint" ctrlrange="-330 330"/><motor name="motor_elbow" joint="elbow_joint" ctrlrange="-150 150"/><motor name="motor_wrist_1" joint="wrist_1_joint" ctrlrange="-54 54"/><motor name="motor_wrist_2" joint="wrist_2_joint" ctrlrange="-54 54"/><motor name="motor_wrist_3" joint="wrist_3_joint" ctrlrange="-54 54"/></actuator></mujoco>
