<mujoco model="ur3">
  <compiler angle="radian" meshdir="C:/Users/smart/Downloads/mat/desc/meshes/ur3/collision"/>
  <asset>
    <mesh name="bases" file="base.stl"/>
    <mesh name="shoulder" file="shoulder.stl"/>
    <mesh name="upperarm" file="upperarm.stl"/>
    <mesh name="forearm" file="forearm.stl"/>
    <mesh name="wrist1" file="wrist1.stl"/>
    <mesh name="wrist2" file="wrist2.stl"/>
    <mesh name="wrist3" file="wrist3.stl"/>
  </asset> 
  <worldbody>
    <body name="base_link">
      <inertial pos="0.000000000 0.000000000 0.000000000" quat="0.5 0.5 -0.5 0.5" mass="2.3" diaginertia="0.005782500 0.003210670 0.003188170"/>
      <geom type="mesh" rgba="0.7 0.7 0.7 1" mesh="bases"/>
      <body name="shoulder_link" pos="0 0 0.1519">
        <inertial pos="0.000000000 0.000000000 0.000000000" mass="2.3" diaginertia="0.008250660 0.008228160 0.005782500"/>
        <joint name="shoulder_pan_joint" pos="0 0 0" axis="0 0 1" range="-6.28319 6.28319" actuatorfrcrange="-330 330" armature="0.000008200"/>
        <geom type="mesh" rgba="0.7 0.7 0.7 1" mesh="shoulder"/>
        <body name="upper_arm_link" pos="0 0.1198 0" quat="0.707107 0 0.707107 0">
          <inertial pos="0.000000000 0.000000000 0.131649597" mass="3.7199999999999998" diaginertia="0.025979335 0.025956835 0.009776250"/>
          <joint name="shoulder_lift_joint" pos="0 0 0" axis="0 1 0" range="-6.28319 6.28319" actuatorfrcrange="-330 330" armature="0.000008200"/>
          <geom type="mesh" rgba="0.7 0.7 0.7 1" mesh="upperarm"/>
          <body name="forearm_link" pos="0 -0.0925 0.24365">
            <inertial pos="0.000000000 0.000000000 0.127129808" mass="1.56" diaginertia="0.009459080 0.009436580 0.003701250"/>
            <joint name="elbow_joint" pos="0 0 0" axis="0 1 0" range="-3.14159 3.14159" actuatorfrcrange="-150 150" armature="0.000008200"/>
            <geom type="mesh" rgba="0.7 0.7 0.7 1" mesh="forearm"/>
            <body name="wrist_1_link" pos="0 0 0.21325" quat="0.707107 0 0.707107 0">
              <inertial pos="0.000000000 0.023195455 0.000000000" quat="0.5 0.5 -0.5 0.5" mass="1.1" diaginertia="0.003985719 0.002242500 0.003798219"/>
              <joint name="wrist_1_joint" pos="0 0 0" axis="0 1 0" range="-6.28319 6.28319" actuatorfrcrange="-54 54" armature="0.000008200"/>
              <geom type="mesh" rgba="0.7 0.7 0.7 1" mesh="wrist1"/>
              <body name="wrist_2_link" pos="0 0.08505 0">
                <inertial pos="0.000000000 0.000000000 0.023277273" quat="0.5 0.5 -0.5 0.5" mass="1.1" diaginertia="0.003996872 0.003809372 0.002242500"/>
                <joint name="wrist_2_joint" pos="0 0 0" axis="0 0 1" range="-6.28319 6.28319" actuatorfrcrange="-54 54" armature="0.000008200"/>
                <geom type="mesh" rgba="0.7 0.7 0.7 1" mesh="wrist2"/>
                <body name="wrist_3_link" pos="0 0 0.08535">
                  <inertial pos="0 0 0" quat="0.5 0.5 -0.5 0.5" mass="0.35" diaginertia="0.000984375 0.000912187 0.000912187"/>
                  <joint name="wrist_3_joint" pos="0 0 0" axis="0 1 0" range="-6.28319 6.28319" actuatorfrcrange="-54 54" armature="0.000008200"/>
                  <geom type="mesh" rgba="0.7 0.7 0.7 1" mesh="wrist3"/>
                  <body name="ee_link" pos="0 0.0819 0" quat="0.707107 0 0 0.707107">
                    <geom size="0.005 0.005 0.005" pos="-0.01 0 0" type="box"/>
                  </body>
                  <body name="tool0" pos="0 0.0819 0" quat="0.707107 -0.707107 0 0"/>
                </body>
              </body>
            </body>
          </body>
        </body>
      </body>
      <body name="base" quat="0 0 0 -1"/>
    </body>
  </worldbody>
  <actuator>
    <position name="j_shoulder_pan_joint" joint="shoulder_pan_joint" kp="0.01" dampratio="1" gear="101" ctrlrange="-317.300858013 317.300858013" forcerange="-8.900000000 8.900000000"/>
    <position name="j_shoulder_lift_joint" joint="shoulder_lift_joint" kp="0.01" dampratio="1" gear="101" ctrlrange="-317.300858013 317.300858013" forcerange="-8.900000000 8.900000000"/>
    <position name="j_elbow_joint" joint="elbow_joint" kp="0.01" dampratio="1" gear="101" ctrlrange="-317.300858013 317.300858013" forcerange="-8.900000000 8.900000000"/>
    <position name="j_wrist_1_joint" joint="wrist_1_joint" kp="0.01" dampratio="1" gear="101" ctrlrange="-317.300858013 317.300858013" forcerange="-8.900000000 8.900000000"/>
    <position name="j_wrist_2_joint" joint="wrist_2_joint" kp="0.01" dampratio="1" gear="101" ctrlrange="-317.300858013 317.300858013" forcerange="-8.900000000 8.900000000"/>
    <position name="j_wrist_3_joint" joint="wrist_3_joint" kp="0.01" dampratio="1" gear="101" ctrlrange="-317.300858013 317.300858013" forcerange="-8.900000000 8.900000000"/>
  </actuator>
  <sensor>
    <jointpos name="s_shoulder_pan_joint" joint="shoulder_pan_joint"/>
    <jointpos name="s_shoulder_lift_joint" joint="shoulder_lift_joint"/>
    <jointpos name="s_elbow_joint" joint="elbow_joint"/>
    <jointpos name="s_wrist_1_joint" joint="wrist_1_joint"/>
    <jointpos name="s_wrist_2_joint" joint="wrist_2_joint"/>
    <jointpos name="s_wrist_3_joint" joint="wrist_3_joint"/>
  </sensor>
</mujoco>
