<mujoco model="ur3">
  <compiler angle="radian" meshdir="C:/Users/smart/Downloads/mat/desc/meshes/ur3/collision/"/>
  <asset>
    <mesh name="bases" file="base.stl"/>
    <mesh name="shoulder" file="shoulder.stl"/>
    <mesh name="upperarm" file="upperarm.stl"/>
    <mesh name="forearm" file="forearm.stl"/>
    <mesh name="wrist1" file="wrist1.stl"/>
    <mesh name="wrist2" file="wrist2.stl"/>
    <mesh name="wrist3" file="wrist3.stl"/>
  </asset>
  <worldbody>
    <body name="base_link">
      <inertial pos="0 0 0" quat="0.5 0.5 -0.5 0.5" mass="2" diaginertia="0.005625 0.00305317 0.00305317"/>
      <geom type="mesh" rgba="0.7 0.7 0.7 1" mesh="bases"/>
      <body name="shoulder_link" pos="0 0 0.1519">
        <inertial pos="0 0 0" mass="2" diaginertia="0.008093160 0.008093160 0.005663200"/>
        <joint name="shoulder_pan_joint" pos="0 0 0" axis="0 0 1" range="-6.28319 6.28319" actuatorfrcrange="-330 330"/>
        <geom type="mesh" rgba="0.7 0.7 0.7 1" mesh="shoulder"/>
        <body name="upper_arm_link" pos="0 0.1198 0" quat="0.707107 0 0.707107 0">
          <inertial pos="0 0 0.121825" mass="3.42" diaginertia="0.021728500 0.021766700 0.009618750"/>
          <joint name="shoulder_lift_joint" pos="0 0 0" axis="0 1 0" range="-6.28319 6.28319" actuatorfrcrange="-330 330"/>
          <geom type="mesh" rgba="0.7 0.7 0.7 1" mesh="upperarm"/>
          <body name="forearm_link" pos="0 -0.0925 0.24365">
            <inertial pos="0 0 0.106625" mass="1.26" diaginertia="0.006546810 0.006585010 0.003543750"/>
            <joint name="elbow_joint" pos="0 0 0" axis="0 1 0" range="-3.14159 3.14159" actuatorfrcrange="-150 150"/>
            <geom type="mesh" rgba="0.7 0.7 0.7 1" mesh="forearm"/>
            <body name="wrist_1_link" pos="0 0 0.21325" quat="0.707107 0 0.707107 0">
              <inertial pos="0 0 0" quat="0.5 0.5 -0.5 0.5" mass="0.8" diaginertia="0.002250000 0.002123200 0.002085000"/>
              <joint name="wrist_1_joint" pos="0 0 0" axis="0 1 0" range="-6.28319 6.28319" actuatorfrcrange="-54 54"/>
              <geom type="mesh" rgba="0.7 0.7 0.7 1" mesh="wrist1"/>
              <body name="wrist_2_link" pos="0 0.08505 0">
                <inertial pos="0 0 0" quat="0.5 0.5 -0.5 0.5" mass="0.8" diaginertia="0.002250000 0.002085000 0.002123200"/>
                <joint name="wrist_2_joint" pos="0 0 0" axis="0 0 1" range="-6.28319 6.28319" actuatorfrcrange="-54 54"/>
                <geom type="mesh" rgba="0.7 0.7 0.7 1" mesh="wrist2"/>
                <body name="wrist_3_link" pos="0 0 0.08535">
                  <inertial pos="0 0 0" quat="0.5 0.5 -0.5 0.5" mass="0.35" diaginertia="0.000984375 0.000950387 0.000912187"/>
                  <joint name="wrist_3_joint" pos="0 0 0" axis="0 1 0" range="-6.28319 6.28319" actuatorfrcrange="-54 54"/>
                  <geom type="mesh" rgba="0.7 0.7 0.7 1" mesh="wrist3"/>
                  <body name="ee_link" pos="0 0.0819 0" quat="0.707107 0 0 0.707107">
                    <geom size="0.005 0.005 0.005" pos="-0.01 0 0" type="box"/>
                  </body>
                  <body name="tool0" pos="0 0.0819 0" quat="0.707107 -0.707107 0 0"/>
                </body>
              </body>
            </body>
          </body>
        </body>
      </body>
      <body name="base" quat="0 0 0 -1"/>
    </body>
  </worldbody>
  <actuator>
    <position name="j_shoulder_pan_joint" joint="shoulder_pan_joint" kp="0.01" dampratio="1" gear="101" ctrlrange="-317.300858013 317.300858013" forcerange="-30.000000000 30.000000000"/>
    <position name="j_shoulder_lift_joint" joint="shoulder_lift_joint" kp="0.01" dampratio="1" gear="101" ctrlrange="-317.300858013 317.300858013" forcerange="-30.000000000 30.000000000"/>
    <position name="j_elbow_joint" joint="elbow_joint" kp="0.01" dampratio="1" gear="101" ctrlrange="-317.300858013 317.300858013" forcerange="-30.000000000 30.000000000"/>
    <position name="j_wrist_1_joint" joint="wrist_1_joint" kp="0.01" dampratio="1" gear="101" ctrlrange="-317.300858013 317.300858013" forcerange="-30.000000000 30.000000000"/>
    <position name="j_wrist_2_joint" joint="wrist_2_joint" kp="0.01" dampratio="1" gear="101" ctrlrange="-317.300858013 317.300858013" forcerange="-30.000000000 30.000000000"/>
    <position name="j_wrist_3_joint" joint="wrist_3_joint" kp="0.01" dampratio="1" gear="101" ctrlrange="-317.300858013 317.300858013" forcerange="-30.000000000 30.000000000"/>
  </actuator>
  <sensor>
    <jointpos name="s_shoulder_pan_joint" joint="shoulder_pan_joint"/>
    <jointpos name="s_shoulder_lift_joint" joint="shoulder_lift_joint"/>
    <jointpos name="s_elbow_joint" joint="elbow_joint"/>
    <jointpos name="s_wrist_1_joint" joint="wrist_1_joint"/>
    <jointpos name="s_wrist_2_joint" joint="wrist_2_joint"/>
    <jointpos name="s_wrist_3_joint" joint="wrist_3_joint"/>
  </sensor>
</mujoco>
